Workbook

Sheet Параметры
A1: Параметры расчёта
A2: Портал Alean Collection · оценка трудозатрат
A4: Жёлтые ячейки — поля для заполнения. Ставки указаны ориентировочно, замените на свои.
A6: Роль | B6: Ставка, ₽/час
A7: Руководитель проекта | B7: 3000
A8: Аналитик | B8: 3000
A9: UX/UI-дизайнер | B9: 3000
A10: Арт-директор | B10: 4500
A11: Технический лид | B11: 4500
A12: Frontend (Next.js) | B12: 3500
A13: Разработчик Битрикс | B13: 3500
A14: DevOps-инженер | B14: 4000
A15: QA-инженер | B15: 2500
A16: SEO-специалист | B16: 3000
A17: Контент-менеджер | B17: 1800
A19: Часов в человеко-месяце | B19: 160
A20: Надбавка за параллелизацию работ | B20: 0.06 | C20: Координационные издержки сжатого графика
A21: Резерв на риски | B21: 0.1 | C21: Неопределённость объёма миграции и доработок по итогам этапа 1
A23: Допущения
A24: • Оценка построена на открытых данных 10 сайтов до получения доступа к базе и админке.
A25: • Учтено, что все 10 сайтов работают на одном шаблоне Битрикса — миграция скриптуема.
A26: • Библиотека блоков — 28 позиций, типов страниц — 17 (desktop + mobile).
A27: • Бронирование остаётся в TravelLine; разработка платёжного контура не входит в объём.
A28: • Личный кабинет и программа лояльности в объём «Запуск» не входят (см. вопрос 6 в концепции).
A29: • Контент мигрируется с текущих сайтов; создание нового контента не входит в объём.
A30: • Ставки в таблице выше — плейсхолдеры, подлежат замене.

Sheet Трудозатраты
A1: Оценка трудозатрат по работам
A2: Часы по ролям. Стоимость рассчитывается автоматически по ставкам с листа «Параметры».
A4: Ставка, ₽/час → | C4: =Параметры!$B$7 -> 3000 | D4: =Параметры!$B$8 -> 3000 | E4: =Параметры!$B$9 -> 3000 | F4: =Параметры!$B$10 -> 4500 | G4: =Параметры!$B$11 -> 4500 | H4: =Параметры!$B$12 -> 3500 | I4: =Параметры!$B$13 -> 3500 | J4: =Параметры!$B$14 -> 4000 | K4: =Параметры!$B$15 -> 2500 | L4: =Параметры!$B$16 -> 3000 | M4: =Параметры!$B$17 -> 1800
A5: ID | B5: Работа | C5: Руководитель проекта | D5: Аналитик | E5: UX/UI-дизайнер | F5: Арт-директор | G5: Технический лид | H5: Frontend (Next.js) | I5: Разработчик Битрикс | J5: DevOps-инженер | K5: QA-инженер | L5: SEO-специалист | M5: Контент-менеджер | N5: Итого часов | O5: Стоимость
B6: ЭТАП 1. АНАЛИТИКА И ДИЗАЙН | C6: =SUM(C7:C21) -> 80 | D6: =SUM(D7:D21) -> 250 | E6: =SUM(E7:E21) -> 580 | F6: =SUM(F7:F21) -> 80 | G6: =SUM(G7:G21) -> 150 | H6: =SUM(H7:H21) -> 0 | I6: =SUM(I7:I21) -> 0 | J6: =SUM(J7:J21) -> 0 | ... O6: =SUM(O7:O21) -> 3915000
A7: 1.1 | B7: Инвентаризация и аудит 10 действующих сайтов | D7: 60 | L7: 20 | N7: =SUM(C7:M7) -> 80 | O7: =SUMPRODUCT(C7:M7,$C$4:$M$4) -> 240000
A8: 1.2 | B8: Воркшопы с заказчиком, уточнение требований | C8: 20 | D8: 40 | G8: 10 | N8: =SUM(C8:M8) -> 70 | O8: =SUMPRODUCT(C8:M8,$C$4:$M$4) -> 225000
A9: 1.3 | B9: Детальное техническое задание на разработку | D9: 80 | G9: 20 | N9: =SUM(C9:M9) -> 100 | O9: =SUMPRODUCT(C9:M9,$C$4:$M$4) -> 330000
A10: 1.4 | B10: Проектирование контент-модели | D10: 40 | G10: 20 | N10: =SUM(C10:M10) -> 60 | O10: =SUMPRODUCT(C10:M10,$C$4:$M$4) -> 210000
A11: 1.5 | B11: Первичная карта URL и инвентаризация редиректов | D11: 30 | L11: 30 | N11: =SUM(C11:M11) -> 60 | O11: =SUMPRODUCT(C11:M11,$C$4:$M$4) -> 180000
A12: 1.6 | B12: Информационная архитектура портала | E12: 40 | N12: =SUM(C12:M12) -> 40 | O12: =SUMPRODUCT(C12:M12,$C$4:$M$4) -> 120000
A13: 1.7 | B13: Прототипы всех типов страниц | E13: 120 | N13: =SUM(C13:M13) -> 120 | O13: =SUMPRODUCT(C13:M13,$C$4:$M$4) -> 360000
A14: 1.8 | B14: Проработка мобильных сценариев | E14: 40 | N14: =SUM(C14:M14) -> 40 | O14: =SUMPRODUCT(C14:M14,$C$4:$M$4) -> 120000
A15: 1.9 | B15: Визуальная концепция, темы «Море» и «Горы» | E15: 20 | F15: 60 | N15: =SUM(C15:M15) -> 80 | O15: =SUMPRODUCT(C15:M15,$C$4:$M$4) -> 330000
A16: 1.10 | B16: Дизайн-система и токены (3 уровня, 7 брендов) | E16: 100 | F16: 20 | N16: =SUM(C16:M16) -> 120 | O16: =SUMPRODUCT(C16:M16,$C$4:$M$4) -> 390000
A17: 1.11 | B17: Макеты типов страниц (17 типов, desktop + mobile) | E17: 160 | N17: =SUM(C17:M17) -> 160 | O17: =SUMPRODUCT(C17:M17,$C$4:$M$4) -> 480000
A18: 1.12 | B18: Дизайн блоков библиотеки (28 шт.) | E18: 100 | N18: =SUM(C18:M18) -> 100 | O18: =SUMPRODUCT(C18:M18,$C$4:$M$4) -> 300000
A19: 1.13 | B19: Архитектура решения, схемы взаимодействия | G19: 60 | N19: =SUM(C19:M19) -> 60 | O19: =SUMPRODUCT(C19:M19,$C$4:$M$4) -> 270000
A20: 1.14 | B20: Контракт контентного API (черновая версия) | G20: 40 | N20: =SUM(C20:M20) -> 40 | O20: =SUMPRODUCT(C20:M20,$C$4:$M$4) -> 180000
A21: 1.15 | B21: Управление этапом | C21: 60 | N21: =SUM(C21:M21) -> 60 | O21: =SUMPRODUCT(C21:M21,$C$4:$M$4) -> 180000
B22: ЭТАП 2. БАЗОВОЕ ЯДРО И АДМИНКА | C22: =SUM(C23:C65) -> 300 | D22: =SUM(D23:D65) -> 120 | E22: =SUM(E23:E65) -> 80 | F22: =SUM(F23:F65) -> 20 | G22: =SUM(G23:G65) -> 200 | H22: =SUM(H23:H65) -> 1380 | I22: =SUM(I23:I65) -> 1080 | J22: =SUM(J23:J65) -> 340 | ... O22: =SUM(O23:O65) -> 14220000
A23: 2.1 | B23: Каркас приложения, роутинг, система тем | H23: 120 | N23: =SUM(C23:M23) -> 120 | O23: =SUMPRODUCT(C23:M23,$C$4:$M$4) -> 420000
A24: 2.2 | B24: Библиотека универсальных блоков (28 шт.) | H24: 400 | N24: =SUM(C24:M24) -> 400 | O24: =SUMPRODUCT(C24:M24,$C$4:$M$4) -> 1400000
A25: 2.3 | B25: Storybook и документация блоков | H25: 60 | N25: =SUM(C25:M25) -> 60 | O25: =SUMPRODUCT(C25:M25,$C$4:$M$4) -> 210000
A26: 2.4 | B26: Главная страница | H26: 40 | N26: =SUM(C26:M26) -> 40 | O26: =SUMPRODUCT(C26:M26,$C$4:$M$4) -> 140000
A27: 2.5 | B27: Каталог отелей с фасетной фильтрацией | H27: 80 | N27: =SUM(C27:M27) -> 80 | O27: =SUMPRODUCT(C27:M27,$C$4:$M$4) -> 280000
A28: 2.6 | B28: Шаблон подсайта отеля и его разделов | H28: 120 | N28: =SUM(C28:M28) -> 120 | O28: =SUMPRODUCT(C28:M28,$C$4:$M$4) -> 420000
A29: 2.7 | B29: Страницы категорий номеров | H29: 40 | N29: =SUM(C29:M29) -> 40 | O29: =SUMPRODUCT(C29:M29,$C$4:$M$4) -> 140000
A30: 2.8 | B30: Общие разделы портала (11 шт.) | H30: 120 | N30: =SUM(C30:M30) -> 120 | O30: =SUMPRODUCT(C30:M30,$C$4:$M$4) -> 420000
A31: 2.9 | B31: Формы: 4 типа, независимые экземпляры | H31: 80 | N31: =SUM(C31:M31) -> 80 | O31: =SUMPRODUCT(C31:M31,$C$4:$M$4) -> 280000
A32: 2.10 | B32: Интеграция виджета TravelLine на витрине | H32: 60 | N32: =SUM(C32:M32) -> 60 | O32: =SUMPRODUCT(C32:M32,$C$4:$M$4) -> 210000
A33: 2.11 | B33: SEO-слой: метатеги, микроразметка, sitemap | H33: 60 | N33: =SUM(C33:M33) -> 60 | O33: =SUMPRODUCT(C33:M33,$C$4:$M$4) -> 210000
A34: 2.12 | B34: Web-push, счётчик обратного отсчёта, попапы | H34: 40 | N34: =SUM(C34:M34) -> 40 | O34: =SUMPRODUCT(C34:M34,$C$4:$M$4) -> 140000
... A36: 2.14 | B36: Адаптивная и кроссбраузерная доводка | H36: 80 | N36: =SUM(C36:M36) -> 80 | O36: =SUMPRODUCT(C36:M36,$C$4:$M$4) -> 280000
A37: 2.15 | B37: Структура инфоблоков под контент-модель | I37: 100 | N37: =SUM(C37:M37) -> 100 | O37: =SUMPRODUCT(C37:M37,$C$4:$M$4) -> 350000
A38: 2.16 | B38: Контентный API и спецификация OpenAPI | I38: 160 | N38: =SUM(C38:M38) -> 160 | O38: =SUMPRODUCT(C38:M38,$C$4:$M$4) -> 560000
A39: 2.17 | B39: Webhook-ревалидация ISR при публикации | I39: 40 | N39: =SUM(C39:M39) -> 40 | O39: =SUMPRODUCT(C39:M39,$C$4:$M$4) -> 140000
A40: 2.18 | B40: Админка: интерфейс конструктора блоков | I40: 160 | N40: =SUM(C40:M40) -> 160 | O40: =SUMPRODUCT(C40:M40,$C$4:$M$4) -> 560000
A41: 2.19 | B41: Управление акциями (логика scope) | I41: 60 | N41: =SUM(C41:M41) -> 60 | O41: =SUMPRODUCT(C41:M41,$C$4:$M$4) -> 210000
A42: 2.20 | B42: Управление SEO и редиректами в админке | I42: 100 | N42: =SUM(C42:M42) -> 100 | O42: =SUMPRODUCT(C42:M42,$C$4:$M$4) -> 350000
...

Sheet Сводка
A1: Сводка
A3: По этапам
A4: Этап | B4: Часов | C4: Чел.-мес. | D4: Доля | E4: Стоимость
A5: ЭТАП 1. АНАЛИТИКА И ДИЗАЙН | B5: =Трудозатраты!N6 -> 1190 | C5: =Трудозатраты!N6/Параметры!$B$19 -> 7.4375 | D5: =Трудозатраты!N6/Трудозатраты!N88 -> 0.17321689 | E5: =Трудозатраты!O6 -> 3915000
A6: ЭТАП 2. БАЗОВОЕ ЯДРО И АДМИНКА | B6: =Трудозатраты!N22 -> 4270 | C6: =Трудозатраты!N22/Параметры!$B$19 -> 26.6875 | D6: =Трудозатраты!N22/Трудозатраты!N88 -> 0.62154294 | E6: =Трудозатраты!O22 -> 14220000
A7: ЭТАП 3. SOFT-LAUNCH И QA | B7: =Трудозатраты!N66 -> 580 | C7: =Трудозатраты!N66/Параметры!$B$19 -> 3.625 | D7: =Трудозатраты!N66/Трудозатраты!N88 -> 0.084425036 | E7: =Трудозатраты!O66 -> 1960000
A8: ЭТАП 4. ВОЛНОВОЕ ПЕРЕКЛЮЧЕНИЕ | B8: =Трудозатраты!N74 -> 530 | C8: =Трудозатраты!N74/Параметры!$B$19 -> 3.3125 | D8: =Трудозатраты!N74/Трудозатраты!N88 -> 0.077147016 | E8: =Трудозатраты!O74 -> 1740000
A9: ЭТАП 5. ЗАВЕРШЕНИЕ И ПЕРЕДАЧА | B9: =Трудозатраты!N81 -> 300 | C9: =Трудозатраты!N81/Параметры!$B$19 -> 1.875 | D9: =Трудозатраты!N81/Трудозатраты!N88 -> 0.043668122 | E9: =Трудозатраты!O81 -> 1050000
A10: Базовая оценка | B10: =SUM(B5:B9) -> 6870 | C10: =B10/Параметры!$B$19 -> 42.9375 | D10: =SUM(D5:D9) -> 1 | E10: =SUM(E5:E9) -> 22885000
A12: Итоговый расчёт
A13: Базовая оценка | B13: =B10 -> 6870 | E13: =E10 -> 22885000
A14: Надбавка за параллелизацию | B14: =B10*Параметры!$B$20 -> 412.2 | E14: =E10*Параметры!$B$20 -> 1373100
A15: Резерв на риски | B15: =B10*Параметры!$B$21 -> 687 | E15: =E10*Параметры!$B$21 -> 2288500
A16: ИТОГО с учётом надбавок | B16: =SUM(B13:B15) -> 7969.2 | C16: =B16/Параметры!$B$19 -> 49.8075 | E16: =SUM(E13:E15) -> 26546600
A18: По ролям
A19: Роль | B19: Часов | C19: Чел.-мес. | D19: Доля | E19: Стоимость
A20: Руководитель проекта | B20: =Трудозатраты!C88 -> 560 | C20: =B20/Параметры!$B$19 -> 3.5 | D20: =B20/Трудозатраты!N88 -> 0.081513828 | E20: =B20*Параметры!$B$7 -> 1680000
A21: Аналитик | B21: =Трудозатраты!D88 -> 460 | C21: =B21/Параметры!$B$19 -> 2.875 | D21: =B21/Трудозатраты!N88 -> 0.066957787 | E21: =B21*Параметры!$B$8 -> 1380000
A22: UX/UI-дизайнер | B22: =Трудозатраты!E88 -> 660 | C22: =B22/Параметры!$B$19 -> 4.125 | D22: =B22/Трудозатраты!N88 -> 0.096069869 | E22: =B22*Параметры!$B$9 -> 1980000
A23: Арт-директор | B23: =Трудозатраты!F88 -> 100 | C23: =B23/Параметры!$B$19 -> 0.625 | D23: =B23/Трудозатраты!N88 -> 0.014556041 | E23: =B23*Параметры!$B$10 -> 450000
A24: Технический лид | B24: =Трудозатраты!G88 -> 410 | C24: =B24/Параметры!$B$19 -> 2.5625 | D24: =B24/Трудозатраты!N88 -> 0.059679767 | E24: =B24*Параметры!$B$11 -> 1845000
A25: Frontend (Next.js) | B25: =Трудозатраты!H88 -> 1590 | C25: =B25/Параметры!$B$19 -> 9.9375 | D25: =B25/Трудозатраты!N88 -> 0.23144105 | E25: =B25*Параметры!$B$12 -> 5565000
A26: Разработчик Битрикс | B26: =Трудозатраты!I88 -> 1310 | C26: =B26/Параметры!$B$19 -> 8.1875 | D26: =B26/Трудозатраты!N88 -> 0.19068413 | E26: =B26*Параметры!$B$13 -> 4585000
A27: DevOps-инженер | B27: =Трудозатраты!J88 -> 610 | C27: =B27/Параметры!$B$19 -> 3.8125 | D27: =B27/Трудозатраты!N88 -> 0.088791849 | E27: =B27*Параметры!$B$14 -> 2440000
A28: QA-инженер | B28: =Трудозатраты!K88 -> 620 | C28: =B28/Параметры!$B$19 -> 3.875 | D28: =B28/Трудозатраты!N88 -> 0.090247453 | E28: =B28*Параметры!$B$15 -> 1550000
A29: SEO-специалист | B29: =Трудозатраты!L88 -> 350 | C29: =B29/Параметры!$B$19 -> 2.1875 | D29: =B29/Трудозатраты!N88 -> 0.050946143 | E29: =B29*Параметры!$B$16 -> 1050000
A30: Контент-менеджер | B30: =Трудозатраты!M88 -> 200 | C30: =B30/Параметры!$B$19 -> 1.25 | D30: =B30/Трудозатраты!N88 -> 0.029112082 | E30: =B30*Параметры!$B$17 -> 360000
A31: Итого | B31: =SUM(B20:B30) -> 6870 | C31: =B31/Параметры!$B$19 -> 42.9375 | D31: =SUM(D20:D30) -> 1 | E31: =SUM(E20:E30) -> 22885000

Sheet Сроки
A1: Календарный график: базовый и сжатый
A2: Сжатие достигается параллелизацией, а не сокращением объёма работ. Трудозатраты те же плюс надбавка за координацию.
A4: Этап | B4: По ТЗ, нед. | C4: Сжатый, нед. | D4: Старт, нед. | E4: Финиш, нед. | F4: За счёт чего сжимаем
A5: 1. Аналитика и дизайн | B5: 3–5 | C5: 4 | D5: 1 | E5: 4 | F5: Прототипы заказчика в Figma берём за основу; 4 дизайнера вместо 2
A6: 2. Базовое ядро и админка | B6: 12–16 | C6: 11 | D6: 3 | E6: 13 | F6: Старт после утверждения дизайн-системы, не всех макетов; блоки и подсайты конвейером
A7: 3. Soft-launch и QA | B7: 2 | C7: 2 | D7: 12 | E7: 13 | F7: Нагрузочное и аудит безопасности внахлёст с концом разработки
A8: 4. Волновое переключение | B8: н/д | C8: 4 | D8: 14 | E8: 17 | F8: Волна 1 стартует, не дожидаясь готовности всех подсайтов
A9: 5. Завершение и передача | B9: н/д | C9: 2 | D9: 16 | E9: 17 | F9: Документация пишется по ходу этапа 2, на финале — только сборка и обучение
A10: Итого календарно | B10: 23–31 | C10: =MAX(E5:E9) -> 17 | F10: 6–7 месяцев по ТЗ → около 4 месяцев в сжатом графике
A12: Условия, без которых сжатый график недостижим
A13: • Доступ к базе, админке, Метрике и Вебмастеру предоставлен в первую неделю этапа 1.
A14: • Ответственный от заказчика с полномочиями принимать решения; согласования не дольше 3 рабочих дней.
A15: • Прототипы Figma и брендбуки переданы на старте.
A16: • Контент мигрируется «как есть»; переписывание текстов — отдельный объём работ.
A17: • Объём библиотеки блоков фиксируется по итогам этапа 1 и не расширяется по ходу этапа 2.
